Workbook

Sheet Input Data Daily
A1: Data Input KPI Produksi Tahunan 2026
A2: Data sumber tahunan untuk dashboard. Input actual harian disimpan di sini. | L2: Target | M2: Nilai
L3: PA | M3: 0.93
A4: Tanggal | B4: PA | C4: UA | D4: Payload | E4: Cycle Time | F4: Fuel Ratio | G4: Unit Running | H4: TDP | I4: Produksi | J4: Keterangan | K4: Kelompok Minggu | L4: UA | M4: 0.88
A5: 46023 | K5: ="W"&TEXT(INT((A5-DATE(2026,1,1))/7)+1,"00") -> W01 | L5: Payload | M5: 205
A6: 46024 | K6: ="W"&TEXT(INT((A6-DATE(2026,1,1))/7)+1,"00") -> W01 | L6: Cycle Time | M6: 7.5
A7: 46025 | K7: ="W"&TEXT(INT((A7-DATE(2026,1,1))/7)+1,"00") -> W01 | L7: Fuel Ratio | M7: 1.55
A8: 46026 | K8: ="W"&TEXT(INT((A8-DATE(2026,1,1))/7)+1,"00") -> W01 | L8: Unit Running | M8: 43
A9: 46027 | K9: ="W"&TEXT(INT((A9-DATE(2026,1,1))/7)+1,"00") -> W01 | L9: TDP | M9: 2.7
A10: 46028 | K10: ="W"&TEXT(INT((A10-DATE(2026,1,1))/7)+1,"00") -> W01 | L10: Produksi Bulanan Dasar | M10: 398000
A11: 46029 | K11: ="W"&TEXT(INT((A11-DATE(2026,1,1))/7)+1,"00") -> W01 | L11: Produksi Harian Dasar | M11: =M10/30 -> 13266.667
A12: 46030 | K12: ="W"&TEXT(INT((A12-DATE(2026,1,1))/7)+1,"00") -> W02 | L12: Produksi Oktober | M12: 671000
A13: 46031 | K13: ="W"&TEXT(INT((A13-DATE(2026,1,1))/7)+1,"00") -> W02 | L13: Produksi Harian Oktober | M13: =M12/31 -> 21645.161
A14: 46032 | K14: ="W"&TEXT(INT((A14-DATE(2026,1,1))/7)+1,"00") -> W02 | L14: Produksi November | M14: 671000
A15: 46033 | K15: ="W"&TEXT(INT((A15-DATE(2026,1,1))/7)+1,"00") -> W02 | L15: Produksi Harian November | M15: =M14/30 -> 22366.667
A16: 46034 | K16: ="W"&TEXT(INT((A16-DATE(2026,1,1))/7)+1,"00") -> W02 | L16: Produksi Desember | M16: 671000
A17: 46035 | K17: ="W"&TEXT(INT((A17-DATE(2026,1,1))/7)+1,"00") -> W02 | L17: Produksi Harian Desember | M17: =M16/31 -> 21645.161
A18: 46036 | K18: ="W"&TEXT(INT((A18-DATE(2026,1,1))/7)+1,"00") -> W02
A19: 46037 | K19: ="W"&TEXT(INT((A19-DATE(2026,1,1))/7)+1,"00") -> W03
A20: 46038 | K20: ="W"&TEXT(INT((A20-DATE(2026,1,1))/7)+1,"00") -> W03
A21: 46039 | K21: ="W"&TEXT(INT((A21-DATE(2026,1,1))/7)+1,"00") -> W03
A22: 46040 | K22: ="W"&TEXT(INT((A22-DATE(2026,1,1))/7)+1,"00") -> W03
A23: 46041 | K23: ="W"&TEXT(INT((A23-DATE(2026,1,1))/7)+1,"00") -> W03
A24: 46042 | K24: ="W"&TEXT(INT((A24-DATE(2026,1,1))/7)+1,"00") -> W03
A25: 46043 | K25: ="W"&TEXT(INT((A25-DATE(2026,1,1))/7)+1,"00") -> W03
A26: 46044 | K26: ="W"&TEXT(INT((A26-DATE(2026,1,1))/7)+1,"00") -> W04
A27: 46045 | K27: ="W"&TEXT(INT((A27-DATE(2026,1,1))/7)+1,"00") -> W04
A28: 46046 | K28: ="W"&TEXT(INT((A28-DATE(2026,1,1))/7)+1,"00") -> W04
A29: 46047 | K29: ="W"&TEXT(INT((A29-DATE(2026,1,1))/7)+1,"00") -> W04
... A216: 46234 | K216: ="W"&TEXT(INT((A216-DATE(2026,1,1))/7)+1,"00") -> W31
A217: 46235 | B217: 0.9577 | C217: 0.47892 | D217: 219.935 | E217: 11.00788 | F217: 1.7722236 | G217: 10 | H217: 1 | I217: 2199.35 | K217: ="W"&TEXT(INT((A217-DATE(2026,1,1))/7)+1,"00") -> W31
A218: 46236 | B218: 1 | C218: 0.48146934 | D218: 203.24091 | E218: 11.555264 | F218: 1.8376087 | G218: 11 | H218: 1 | I218: 2235.65 | K218: ="W"&TEXT(INT((A218-DATE(2026,1,1))/7)+1,"00") -> W31
A219: 46237 | B219: 0.9765 | C219: 0.50365248 | D219: 204.71538 | E219: 10.89563 | F219: 1.6846654 | G219: 12 | H219: 1.0833333 | I219: 2661.3 | K219: ="W"&TEXT(INT((A219-DATE(2026,1,1))/7)+1,"00") -> W31
A220: 46238 | B220: 0.9935 | C220: 0.49308276 | D220: 201.17667 | E220: 10.973261 | F220: 1.8657167 | G220: 14 | H220: 1.0714286 | I220: 3017.65 | K220: ="W"&TEXT(INT((A220-DATE(2026,1,1))/7)+1,"00") -> W31
A221: 46239 | B221: 0.9765 | C221: 0.51424211 | D221: 206.70667 | E221: 12.051778 | F221: 1.798468 | G221: 15 | H221: 1 | I221: 3100.6 | K221: ="W"&TEXT(INT((A221-DATE(2026,1,1))/7)+1,"00") -> W31
A222: 46240 | B222: 0.968 | C222: 0.5419962 | D222: 209.99211 | E222: 9.9407808 | F222: 1.5052195 | G222: 15 | H222: 1.2666667 | I222: 3989.85 | K222: ="W"&TEXT(INT((A222-DATE(2026,1,1))/7)+1,"00") -> W32
A223: 46241 | B223: 0.9756 | C223: 0.4948951 | D223: 201.57333 | E223: 11.587672 | F223: 1.8835362 | G223: 15 | H223: 1 | I223: 3023.6 | K223: ="W"&TEXT(INT((A223-DATE(2026,1,1))/7)+1,"00") -> W32
A224: 46242 | B224: 0.9763 | C224: 0.52855082 | D224: 203.46842 | E224: 10.42912 | F224: 1.5061926 | G224: 16 | H224: 1.1875 | I224: 3865.9 | K224: ="W"&TEXT(INT((A224-DATE(2026,1,1))/7)+1,"00") -> W32
A225: 46243 | B225: 0.9814 | C225: 0.48128457 | D225: 202.35 | E225: 9.5460921 | F225: 1.6020106 | G225: 16 | H225: 1.1875 | I225: 3844.65 | K225: ="W"&TEXT(INT((A225-DATE(2026,1,1))/7)+1,"00") -> W32
A226: 46244 | B226: 0.982 | C226: 0.49192972 | D226: 197.95294 | E226: 10.911811 | F226: 1.7794009 | G226: 16 | H226: 1.0625 | I226: 3365.2 | K226: ="W"&TEXT(INT((A226-DATE(2026,1,1))/7)+1,"00") -> W32
...

Sheet Grafik KPI 2026
A1: Grafik Pencapaian KPI Produksi 2026
A2: Pencapaian aktual dikelompokkan mengikuti Kelompok Minggu (W01–W53) pada data harian.
A4: KPI | B4: Target | D4: Bulan | E4: Target Produksi (Ton)
A5: PA | B5: 0.93 | D5: 46235 | E5: 32000
A6: UA | B6: 0.88 | D6: 46266 | E6: 398000
A7: TPD | B7: 2.7 | D7: 46296 | E7: 671000
A8: Cycle Time | B8: 7.5
A9: Payload | B9: 205
A10: Fuel Ratio | B10: 1.55
A11: Produksi | B11: Target bulanan tersedia Aug–Okt
A13: Pencapaian KPI Mingguan
A14: Kelompok Minggu | B14: PA Actual | C14: PA Target | D14: UA Actual | E14: UA Target | F14: Payload Actual | G14: Payload Target | H14: Cycle Time Actual | I14: Cycle Time Target | J14: Fuel Ratio Actual | K14: Fuel Ratio Target | L14: TPD Actual | M14: TPD Target | N14: Produksi Actual (Ton)
A15: =INDEX('Input Data Daily'!$K$5:$K$369,(ROW()-15)*7+1) -> W01 | B15: =IF(COUNTIFS('Input Data Daily'!$K$5:$K$369,$A15,'Input Data Daily'!$B$5:$B$369,"<>")=0,"",AVERAGEIF('Input Data Daily'!$K$5:$K$369,$A15,'Input Data Daily'!$B$5:$B$369)) | C15: =$B$5 -> 0.93 | D15: =IF(COUNTIFS('Input Data Daily'!$K$5:$K$369,$A15,'Input Data Daily'!$C$5:$C$369,"<>")=0,"",AVERAGEIF('Input Data Daily'!$K$5:$K$369,$A15,'Input Data Daily'!$C$5:$C$369)) | E15: =$B$6 -> 0.88 | F15: =IF(COUNTIFS('Input Data Daily'!$K$5:$K$369,$A15,'Input Data Daily'!$D$5:$D$369,"<>")=0,"",AVERAGEIF('Input Data Daily'!$K$5:$K$369,$A15,'Input Data Daily'!$D$5:$D$369)) | G15: =$B$9 -> 205 | H15: =IF(COUNTIFS('Input Data Daily'!$K$5:$K$369,$A15,'Input Data Daily'!$E$5:$E$369,"<>")=0,"",AVERAGEIF('Input Data Daily'!$K$5:$K$369,$A15,'Input Data Daily'!$E$5:$E$369)) | I15: =$B$8 -> 7.5 | J15: =IF(COUNTIFS('Input Data Daily'!$K$5:$K$369,$A15,'Input Data Daily'!$F$5:$F$369,"<>")=0,"",AVERAGEIF('Input Data Daily'!$K$5:$K$369,$A15,'Input Data Daily'!$F$5:$F$369)) | K15: =$B$10 -> 1.55 | L15: =IF(COUNTIFS('Input Data Daily'!$K$5:$K$369,$A15,'Input Data Daily'!$H$5:$H$369,"<>")=0,"",AVERAGEIF('Input Data Daily'!$K$5:$K$369,$A15,'Input Data Daily'!$H$5:$H$369)) | M15: =$B$7 -> 2.7 | N15: =SUMIF('Input Data Daily'!$K$5:$K$369,$A15,'Input Data Daily'!$I$5:$I$369) -> 0
A16: =INDEX('Input Data Daily'!$K$5:$K$369,(ROW()-15)*7+1) -> W02 | B16: =IF(COUNTIFS('Input Data Daily'!$K$5:$K$369,$A16,'Input Data Daily'!$B$5:$B$369,"<>")=0,"",AVERAGEIF('Input Data Daily'!$K$5:$K$369,$A16,'Input Data Daily'!$B$5:$B$369)) | C16: =$B$5 -> 0.93 | D16: =IF(COUNTIFS('Input Data Daily'!$K$5:$K$369,$A16,'Input Data Daily'!$C$5:$C$369,"<>")=0,"",AVERAGEIF('Input Data Daily'!$K$5:$K$369,$A16,'Input Data Daily'!$C$5:$C$369)) | E16: =$B$6 -> 0.88 | F16: =IF(COUNTIFS('Input Data Daily'!$K$5:$K$369,$A16,'Input Data Daily'!$D$5:$D$369,"<>")=0,"",AVERAGEIF('Input Data Daily'!$K$5:$K$369,$A16,'Input Data Daily'!$D$5:$D$369)) | G16: =$B$9 -> 205 | H16: =IF(COUNTIFS('Input Data Daily'!$K$5:$K$369,$A16,'Input Data Daily'!$E$5:$E$369,"<>")=0,"",AVERAGEIF('Input Data Daily'!$K$5:$K$369,$A16,'Input Data Daily'!$E$5:$E$369)) | I16: =$B$8 -> 7.5 | J16: =IF(COUNTIFS('Input Data Daily'!$K$5:$K$369,$A16,'Input Data Daily'!$F$5:$F$369,"<>")=0,"",AVERAGEIF('Input Data Daily'!$K$5:$K$369,$A16,'Input Data Daily'!$F$5:$F$369)) | K16: =$B$10 -> 1.55 | L16: =IF(COUNTIFS('Input Data Daily'!$K$5:$K$369,$A16,'Input Data Daily'!$H$5:$H$369,"<>")=0,"",AVERAGEIF('Input Data Daily'!$K$5:$K$369,$A16,'Input Data Daily'!$H$5:$H$369)) | M16: =$B$7 -> 2.7 | N16: =SUMIF('Input Data Daily'!$K$5:$K$369,$A16,'Input Data Daily'!$I$5:$I$369) -> 0
A17: =INDEX('Input Data Daily'!$K$5:$K$369,(ROW()-15)*7+1) -> W03 | B17: =IF(COUNTIFS('Input Data Daily'!$K$5:$K$369,$A17,'Input Data Daily'!$B$5:$B$369,"<>")=0,"",AVERAGEIF('Input Data Daily'!$K$5:$K$369,$A17,'Input Data Daily'!$B$5:$B$369)) | C17: =$B$5 -> 0.93 | D17: =IF(COUNTIFS('Input Data Daily'!$K$5:$K$369,$A17,'Input Data Daily'!$C$5:$C$369,"<>")=0,"",AVERAGEIF('Input Data Daily'!$K$5:$K$369,$A17,'Input Data Daily'!$C$5:$C$369)) | E17: =$B$6 -> 0.88 | F17: =IF(COUNTIFS('Input Data Daily'!$K$5:$K$369,$A17,'Input Data Daily'!$D$5:$D$369,"<>")=0,"",AVERAGEIF('Input Data Daily'!$K$5:$K$369,$A17,'Input Data Daily'!$D$5:$D$369)) | G17: =$B$9 -> 205 | H17: =IF(COUNTIFS('Input Data Daily'!$K$5:$K$369,$A17,'Input Data Daily'!$E$5:$E$369,"<>")=0,"",AVERAGEIF('Input Data Daily'!$K$5:$K$369,$A17,'Input Data Daily'!$E$5:$E$369)) | I17: =$B$8 -> 7.5 | J17: =IF(COUNTIFS('Input Data Daily'!$K$5:$K$369,$A17,'Input Data Daily'!$F$5:$F$369,"<>")=0,"",AVERAGEIF('Input Data Daily'!$K$5:$K$369,$A17,'Input Data Daily'!$F$5:$F$369)) | K17: =$B$10 -> 1.55 | L17: =IF(COUNTIFS('Input Data Daily'!$K$5:$K$369,$A17,'Input Data Daily'!$H$5:$H$369,"<>")=0,"",AVERAGEIF('Input Data Daily'!$K$5:$K$369,$A17,'Input Data Daily'!$H$5:$H$369)) | M17: =$B$7 -> 2.7 | N17: =SUMIF('Input Data Daily'!$K$5:$K$369,$A17,'Input Data Daily'!$I$5:$I$369) -> 0
A18: =INDEX('Input Data Daily'!$K$5:$K$369,(ROW()-15)*7+1) -> W04 | B18: =IF(COUNTIFS('Input Data Daily'!$K$5:$K$369,$A18,'Input Data Daily'!$B$5:$B$369,"<>")=0,"",AVERAGEIF('Input Data Daily'!$K$5:$K$369,$A18,'Input Data Daily'!$B$5:$B$369)) | C18: =$B$5 -> 0.93 | D18: =IF(COUNTIFS('Input Data Daily'!$K$5:$K$369,$A18,'Input Data Daily'!$C$5:$C$369,"<>")=0,"",AVERAGEIF('Input Data Daily'!$K$5:$K$369,$A18,'Input Data Daily'!$C$5:$C$369)) | E18: =$B$6 -> 0.88 | F18: =IF(COUNTIFS('Input Data Daily'!$K$5:$K$369,$A18,'Input Data Daily'!$D$5:$D$369,"<>")=0,"",AVERAGEIF('Input Data Daily'!$K$5:$K$369,$A18,'Input Data Daily'!$D$5:$D$369)) | G18: =$B$9 -> 205 | H18: =IF(COUNTIFS('Input Data Daily'!$K$5:$K$369,$A18,'Input Data Daily'!$E$5:$E$369,"<>")=0,"",AVERAGEIF('Input Data Daily'!$K$5:$K$369,$A18,'Input Data Daily'!$E$5:$E$369)) | I18: =$B$8 -> 7.5 | J18: =IF(COUNTIFS('Input Data Daily'!$K$5:$K$369,$A18,'Input Data Daily'!$F$5:$F$369,"<>")=0,"",AVERAGEIF('Input Data Daily'!$K$5:$K$369,$A18,'Input Data Daily'!$F$5:$F$369)) | K18: =$B$10 -> 1.55 | L18: =IF(COUNTIFS('Input Data Daily'!$K$5:$K$369,$A18,'Input Data Daily'!$H$5:$H$369,"<>")=0,"",AVERAGEIF('Input Data Daily'!$K$5:$K$369,$A18,'Input Data Daily'!$H$5:$H$369)) | M18: =$B$7 -> 2.7 | N18: =SUMIF('Input Data Daily'!$K$5:$K$369,$A18,'Input Data Daily'!$I$5:$I$369) -> 0
A19: =INDEX('Input Data Daily'!$K$5:$K$369,(ROW()-15)*7+1) -> W05 | B19: =IF(COUNTIFS('Input Data Daily'!$K$5:$K$369,$A19,'Input Data Daily'!$B$5:$B$369,"<>")=0,"",AVERAGEIF('Input Data Daily'!$K$5:$K$369,$A19,'Input Data Daily'!$B$5:$B$369)) | C19: =$B$5 -> 0.93 | D19: =IF(COUNTIFS('Input Data Daily'!$K$5:$K$369,$A19,'Input Data Daily'!$C$5:$C$369,"<>")=0,"",AVERAGEIF('Input Data Daily'!$K$5:$K$369,$A19,'Input Data Daily'!$C$5:$C$369)) | E19: =$B$6 -> 0.88 | F19: =IF(COUNTIFS('Input Data Daily'!$K$5:$K$369,$A19,'Input Data Daily'!$D$5:$D$369,"<>")=0,"",AVERAGEIF('Input Data Daily'!$K$5:$K$369,$A19,'Input Data Daily'!$D$5:$D$369)) | G19: =$B$9 -> 205 | H19: =IF(COUNTIFS('Input Data Daily'!$K$5:$K$369,$A19,'Input Data Daily'!$E$5:$E$369,"<>")=0,"",AVERAGEIF('Input Data Daily'!$K$5:$K$369,$A19,'Input Data Daily'!$E$5:$E$369)) | I19: =$B$8 -> 7.5 | J19: =IF(COUNTIFS('Input Data Daily'!$K$5:$K$369,$A19,'Input Data Daily'!$F$5:$F$369,"<>")=0,"",AVERAGEIF('Input Data Daily'!$K$5:$K$369,$A19,'Input Data Daily'!$F$5:$F$369)) | K19: =$B$10 -> 1.55 | L19: =IF(COUNTIFS('Input Data Daily'!$K$5:$K$369,$A19,'Input Data Daily'!$H$5:$H$369,"<>")=0,"",AVERAGEIF('Input Data Daily'!$K$5:$K$369,$A19,'Input Data Daily'!$H$5:$H$369)) | M19: =$B$7 -> 2.7 | N19: =SUMIF('Input Data Daily'!$K$5:$K$369,$A19,'Input Data Daily'!$I$5:$I$369) -> 0
A20: =INDEX('Input Data Daily'!$K$5:$K$369,(ROW()-15)*7+1) -> W06 | B20: =IF(COUNTIFS('Input Data Daily'!$K$5:$K$369,$A20,'Input Data Daily'!$B$5:$B$369,"<>")=0,"",AVERAGEIF('Input Data Daily'!$K$5:$K$369,$A20,'Input Data Daily'!$B$5:$B$369)) | C20: =$B$5 -> 0.93 | D20: =IF(COUNTIFS('Input Data Daily'!$K$5:$K$369,$A20,'Input Data Daily'!$C$5:$C$369,"<>")=0,"",AVERAGEIF('Input Data Daily'!$K$5:$K$369,$A20,'Input Data Daily'!$C$5:$C$369)) | E20: =$B$6 -> 0.88 | F20: =IF(COUNTIFS('Input Data Daily'!$K$5:$K$369,$A20,'Input Data Daily'!$D$5:$D$369,"<>")=0,"",AVERAGEIF('Input Data Daily'!$K$5:$K$369,$A20,'Input Data Daily'!$D$5:$D$369)) | G20: =$B$9 -> 205 | H20: =IF(COUNTIFS('Input Data Daily'!$K$5:$K$369,$A20,'Input Data Daily'!$E$5:$E$369,"<>")=0,"",AVERAGEIF('Input Data Daily'!$K$5:$K$369,$A20,'Input Data Daily'!$E$5:$E$369)) | I20: =$B$8 -> 7.5 | J20: =IF(COUNTIFS('Input Data Daily'!$K$5:$K$369,$A20,'Input Data Daily'!$F$5:$F$369,"<>")=0,"",AVERAGEIF('Input Data Daily'!$K$5:$K$369,$A20,'Input Data Daily'!$F$5:$F$369)) | K20: =$B$10 -> 1.55 | L20: =IF(COUNTIFS('Input Data Daily'!$K$5:$K$369,$A20,'Input Data Daily'!$H$5:$H$369,"<>")=0,"",AVERAGEIF('Input Data Daily'!$K$5:$K$369,$A20,'Input Data Daily'!$H$5:$H$369)) | M20: =$B$7 -> 2.7 | N20: =SUMIF('Input Data Daily'!$K$5:$K$369,$A20,'Input Data Daily'!$I$5:$I$369) -> 0
A21: =INDEX('Input Data Daily'!$K$5:$K$369,(ROW()-15)*7+1) -> W07 | B21: =IF(COUNTIFS('Input Data Daily'!$K$5:$K$369,$A21,'Input Data Daily'!$B$5:$B$369,"<>")=0,"",AVERAGEIF('Input Data Daily'!$K$5:$K$369,$A21,'Input Data Daily'!$B$5:$B$369)) | C21: =$B$5 -> 0.93 | D21: =IF(COUNTIFS('Input Data Daily'!$K$5:$K$369,$A21,'Input Data Daily'!$C$5:$C$369,"<>")=0,"",AVERAGEIF('Input Data Daily'!$K$5:$K$369,$A21,'Input Data Daily'!$C$5:$C$369)) | E21: =$B$6 -> 0.88 | F21: =IF(COUNTIFS('Input Data Daily'!$K$5:$K$369,$A21,'Input Data Daily'!$D$5:$D$369,"<>")=0,"",AVERAGEIF('Input Data Daily'!$K$5:$K$369,$A21,'Input Data Daily'!$D$5:$D$369)) | G21: =$B$9 -> 205 | H21: =IF(COUNTIFS('Input Data Daily'!$K$5:$K$369,$A21,'Input Data Daily'!$E$5:$E$369,"<>")=0,"",AVERAGEIF('Input Data Daily'!$K$5:$K$369,$A21,'Input Data Daily'!$E$5:$E$369)) | I21: =$B$8 -> 7.5 | J21: =IF(COUNTIFS('Input Data Daily'!$K$5:$K$369,$A21,'Input Data Daily'!$F$5:$F$369,"<>")=0,"",AVERAGEIF('Input Data Daily'!$K$5:$K$369,$A21,'Input Data Daily'!$F$5:$F$369)) | K21: =$B$10 -> 1.55 | L21: =IF(COUNTIFS('Input Data Daily'!$K$5:$K$369,$A21,'Input Data Daily'!$H$5:$H$369,"<>")=0,"",AVERAGEIF('Input Data Daily'!$K$5:$K$369,$A21,'Input Data Daily'!$H$5:$H$369)) | M21: =$B$7 -> 2.7 | N21: =SUMIF('Input Data Daily'!$K$5:$K$369,$A21,'Input Data Daily'!$I$5:$I$369) -> 0
A22: =INDEX('Input Data Daily'!$K$5:$K$369,(ROW()-15)*7+1) -> W08 | B22: =IF(COUNTIFS('Input Data Daily'!$K$5:$K$369,$A22,'Input Data Daily'!$B$5:$B$369,"<>")=0,"",AVERAGEIF('Input Data Daily'!$K$5:$K$369,$A22,'Input Data Daily'!$B$5:$B$369)) | C22: =$B$5 -> 0.93 | D22: =IF(COUNTIFS('Input Data Daily'!$K$5:$K$369,$A22,'Input Data Daily'!$C$5:$C$369,"<>")=0,"",AVERAGEIF('Input Data Daily'!$K$5:$K$369,$A22,'Input Data Daily'!$C$5:$C$369)) | E22: =$B$6 -> 0.88 | F22: =IF(COUNTIFS('Input Data Daily'!$K$5:$K$369,$A22,'Input Data Daily'!$D$5:$D$369,"<>")=0,"",AVERAGEIF('Input Data Daily'!$K$5:$K$369,$A22,'Input Data Daily'!$D$5:$D$369)) | G22: =$B$9 -> 205 | H22: =IF(COUNTIFS('Input Data Daily'!$K$5:$K$369,$A22,'Input Data Daily'!$E$5:$E$369,"<>")=0,"",AVERAGEIF('Input Data Daily'!$K$5:$K$369,$A22,'Input Data Daily'!$E$5:$E$369)) | I22: =$B$8 -> 7.5 | J22: =IF(COUNTIFS('Input Data Daily'!$K$5:$K$369,$A22,'Input Data Daily'!$F$5:$F$369,"<>")=0,"",AVERAGEIF('Input Data Daily'!$K$5:$K$369,$A22,'Input Data Daily'!$F$5:$F$369)) | K22: =$B$10 -> 1.55 | L22: =IF(COUNTIFS('Input Data Daily'!$K$5:$K$369,$A22,'Input Data Daily'!$H$5:$H$369,"<>")=0,"",AVERAGEIF('Input Data Daily'!$K$5:$K$369,$A22,'Input Data Daily'!$H$5:$H$369)) | M22: =$B$7 -> 2.7 | N22: =SUMIF('Input Data Daily'!$K$5:$K$369,$A22,'Input Data Daily'!$I$5:$I$369) -> 0
A23: =INDEX('Input Data Daily'!$K$5:$K$369,(ROW()-15)*7+1) -> W09 | B23: =IF(COUNTIFS('Input Data Daily'!$K$5:$K$369,$A23,'Input Data Daily'!$B$5:$B$369,"<>")=0,"",AVERAGEIF('Input Data Daily'!$K$5:$K$369,$A23,'Input Data Daily'!$B$5:$B$369)) | C23: =$B$5 -> 0.93 | D23: =IF(COUNTIFS('Input Data Daily'!$K$5:$K$369,$A23,'Input Data Daily'!$C$5:$C$369,"<>")=0,"",AVERAGEIF('Input Data Daily'!$K$5:$K$369,$A23,'Input Data Daily'!$C$5:$C$369)) | E23: =$B$6 -> 0.88 | F23: =IF(COUNTIFS('Input Data Daily'!$K$5:$K$369,$A23,'Input Data Daily'!$D$5:$D$369,"<>")=0,"",AVERAGEIF('Input Data Daily'!$K$5:$K$369,$A23,'Input Data Daily'!$D$5:$D$369)) | G23: =$B$9 -> 205 | H23: =IF(COUNTIFS('Input Data Daily'!$K$5:$K$369,$A23,'Input Data Daily'!$E$5:$E$369,"<>")=0,"",AVERAGEIF('Input Data Daily'!$K$5:$K$369,$A23,'Input Data Daily'!$E$5:$E$369)) | I23: =$B$8 -> 7.5 | J23: =IF(COUNTIFS('Input Data Daily'!$K$5:$K$369,$A23,'Input Data Daily'!$F$5:$F$369,"<>")=0,"",AVERAGEIF('Input Data Daily'!$K$5:$K$369,$A23,'Input Data Daily'!$F$5:$F$369)) | K23: =$B$10 -> 1.55 | L23: =IF(COUNTIFS('Input Data Daily'!$K$5:$K$369,$A23,'Input Data Daily'!$H$5:$H$369,"<>")=0,"",AVERAGEIF('Input Data Daily'!$K$5:$K$369,$A23,'Input Data Daily'!$H$5:$H$369)) | M23: =$B$7 -> 2.7 | N23: =SUMIF('Input Data Daily'!$K$5:$K$369,$A23,'Input Data Daily'!$I$5:$I$369) -> 0
A24: =INDEX('Input Data Daily'!$K$5:$K$369,(ROW()-15)*7+1) -> W10 | B24: =IF(COUNTIFS('Input Data Daily'!$K$5:$K$369,$A24,'Input Data Daily'!$B$5:$B$369,"<>")=0,"",AVERAGEIF('Input Data Daily'!$K$5:$K$369,$A24,'Input Data Daily'!$B$5:$B$369)) | C24: =$B$5 -> 0.93 | D24: =IF(COUNTIFS('Input Data Daily'!$K$5:$K$369,$A24,'Input Data Daily'!$C$5:$C$369,"<>")=0,"",AVERAGEIF('Input Data Daily'!$K$5:$K$369,$A24,'Input Data Daily'!$C$5:$C$369)) | E24: =$B$6 -> 0.88 | F24: =IF(COUNTIFS('Input Data Daily'!$K$5:$K$369,$A24,'Input Data Daily'!$D$5:$D$369,"<>")=0,"",AVERAGEIF('Input Data Daily'!$K$5:$K$369,$A24,'Input Data Daily'!$D$5:$D$369)) | G24: =$B$9 -> 205 | H24: =IF(COUNTIFS('Input Data Daily'!$K$5:$K$369,$A24,'Input Data Daily'!$E$5:$E$369,"<>")=0,"",AVERAGEIF('Input Data Daily'!$K$5:$K$369,$A24,'Input Data Daily'!$E$5:$E$369)) | I24: =$B$8 -> 7.5 | J24: =IF(COUNTIFS('Input Data Daily'!$K$5:$K$369,$A24,'Input Data Daily'!$F$5:$F$369,"<>")=0,"",AVERAGEIF('Input Data Daily'!$K$5:$K$369,$A24,'Input Data Daily'!$F$5:$F$369)) | K24: =$B$10 -> 1.55 | L24: =IF(COUNTIFS('Input Data Daily'!$K$5:$K$369,$A24,'Input Data Daily'!$H$5:$H$369,"<>")=0,"",AVERAGEIF('Input Data Daily'!$K$5:$K$369,$A24,'Input Data Daily'!$H$5:$H$369)) | M24: =$B$7 -> 2.7 | N24: =SUMIF('Input Data Daily'!$K$5:$K$369,$A24,'Input Data Daily'!$I$5:$I$369) -> 0
A25: =INDEX('Input Data Daily'!$K$5:$K$369,(ROW()-15)*7+1) -> W11 | B25: =IF(COUNTIFS('Input Data Daily'!$K$5:$K$369,$A25,'Input Data Daily'!$B$5:$B$369,"<>")=0,"",AVERAGEIF('Input Data Daily'!$K$5:$K$369,$A25,'Input Data Daily'!$B$5:$B$369)) | C25: =$B$5 -> 0.93 | D25: =IF(COUNTIFS('Input Data Daily'!$K$5:$K$369,$A25,'Input Data Daily'!$C$5:$C$369,"<>")=0,"",AVERAGEIF('Input Data Daily'!$K$5:$K$369,$A25,'Input Data Daily'!$C$5:$C$369)) | E25: =$B$6 -> 0.88 | F25: =IF(COUNTIFS('Input Data Daily'!$K$5:$K$369,$A25,'Input Data Daily'!$D$5:$D$369,"<>")=0,"",AVERAGEIF('Input Data Daily'!$K$5:$K$369,$A25,'Input Data Daily'!$D$5:$D$369)) | G25: =$B$9 -> 205 | H25: =IF(COUNTIFS('Input Data Daily'!$K$5:$K$369,$A25,'Input Data Daily'!$E$5:$E$369,"<>")=0,"",AVERAGEIF('Input Data Daily'!$K$5:$K$369,$A25,'Input Data Daily'!$E$5:$E$369)) | I25: =$B$8 -> 7.5 | J25: =IF(COUNTIFS('Input Data Daily'!$K$5:$K$369,$A25,'Input Data Daily'!$F$5:$F$369,"<>")=0,"",AVERAGEIF('Input Data Daily'!$K$5:$K$369,$A25,'Input Data Daily'!$F$5:$F$369)) | K25: =$B$10 -> 1.55 | L25: =IF(COUNTIFS('Input Data Daily'!$K$5:$K$369,$A25,'Input Data Daily'!$H$5:$H$369,"<>")=0,"",AVERAGEIF('Input Data Daily'!$K$5:$K$369,$A25,'Input Data Daily'!$H$5:$H$369)) | M25: =$B$7 -> 2.7 | N25: =SUMIF('Input Data Daily'!$K$5:$K$369,$A25,'Input Data Daily'!$I$5:$I$369) -> 0
A26: =INDEX('Input Data Daily'!$K$5:$K$369,(ROW()-15)*7+1) -> W12 | B26: =IF(COUNTIFS('Input Data Daily'!$K$5:$K$369,$A26,'Input Data Daily'!$B$5:$B$369,"<>")=0,"",AVERAGEIF('Input Data Daily'!$K$5:$K$369,$A26,'Input Data Daily'!$B$5:$B$369)) | C26: =$B$5 -> 0.93 | D26: =IF(COUNTIFS('Input Data Daily'!$K$5:$K$369,$A26,'Input Data Daily'!$C$5:$C$369,"<>")=0,"",AVERAGEIF('Input Data Daily'!$K$5:$K$369,$A26,'Input Data Daily'!$C$5:$C$369)) | E26: =$B$6 -> 0.88 | F26: =IF(COUNTIFS('Input Data Daily'!$K$5:$K$369,$A26,'Input Data Daily'!$D$5:$D$369,"<>")=0,"",AVERAGEIF('Input Data Daily'!$K$5:$K$369,$A26,'Input Data Daily'!$D$5:$D$369)) | G26: =$B$9 -> 205 | H26: =IF(COUNTIFS('Input Data Daily'!$K$5:$K$369,$A26,'Input Data Daily'!$E$5:$E$369,"<>")=0,"",AVERAGEIF('Input Data Daily'!$K$5:$K$369,$A26,'Input Data Daily'!$E$5:$E$369)) | I26: =$B$8 -> 7.5 | J26: =IF(COUNTIFS('Input Data Daily'!$K$5:$K$369,$A26,'Input Data Daily'!$F$5:$F$369,"<>")=0,"",AVERAGEIF('Input Data Daily'!$K$5:$K$369,$A26,'Input Data Daily'!$F$5:$F$369)) | K26: =$B$10 -> 1.55 | L26: =IF(COUNTIFS('Input Data Daily'!$K$5:$K$369,$A26,'Input Data Daily'!$H$5:$H$369,"<>")=0,"",AVERAGEIF('Input Data Daily'!$K$5:$K$369,$A26,'Input Data Daily'!$H$5:$H$369)) | M26: =$B$7 -> 2.7 | N26: =SUMIF('Input Data Daily'!$K$5:$K$369,$A26,'Input Data Daily'!$I$5:$I$369) -> 0
... A67: =INDEX('Input Data Daily'!$K$5:$K$369,(ROW()-15)*7+1) -> W53 | B67: =IF(COUNTIFS('Input Data Daily'!$K$5:$K$369,$A67,'Input Data Daily'!$B$5:$B$369,"<>")=0,"",AVERAGEIF('Input Data Daily'!$K$5:$K$369,$A67,'Input Data Daily'!$B$5:$B$369)) | C67: =$B$5 -> 0.93 | D67: =IF(COUNTIFS('Input Data Daily'!$K$5:$K$369,$A67,'Input Data Daily'!$C$5:$C$369,"<>")=0,"",AVERAGEIF('Input Data Daily'!$K$5:$K$369,$A67,'Input Data Daily'!$C$5:$C$369)) | E67: =$B$6 -> 0.88 | F67: =IF(COUNTIFS('Input Data Daily'!$K$5:$K$369,$A67,'Input Data Daily'!$D$5:$D$369,"<>")=0,"",AVERAGEIF('Input Data Daily'!$K$5:$K$369,$A67,'Input Data Daily'!$D$5:$D$369)) | G67: =$B$9 -> 205 | H67: =IF(COUNTIFS('Input Data Daily'!$K$5:$K$369,$A67,'Input Data Daily'!$E$5:$E$369,"<>")=0,"",AVERAGEIF('Input Data Daily'!$K$5:$K$369,$A67,'Input Data Daily'!$E$5:$E$369)) | I67: =$B$8 -> 7.5 | J67: =IF(COUNTIFS('Input Data Daily'!$K$5:$K$369,$A67,'Input Data Daily'!$F$5:$F$369,"<>")=0,"",AVERAGEIF('Input Data Daily'!$K$5:$K$369,$A67,'Input Data Daily'!$F$5:$F$369)) | K67: =$B$10 -> 1.55 | L67: =IF(COUNTIFS('Input Data Daily'!$K$5:$K$369,$A67,'Input Data Daily'!$H$5:$H$369,"<>")=0,"",AVERAGEIF('Input Data Daily'!$K$5:$K$369,$A67,'Input Data Daily'!$H$5:$H$369)) | M67: =$B$7 -> 2.7 | N67: =SUMIF('Input Data Daily'!$K$5:$K$369,$A67,'Input Data Daily'!$I$5:$I$369) -> 0
A70: Bulan | B70: Produksi Actual (Ton) | C70: Target Produksi (Ton) | P70: Kelompok Minggu | Q70: PA Actual | R70: PA Target | T70: Kelompok Minggu | U70: UA Actual | V70: UA Target | X70: Kelompok Minggu | Y70: Payload Actual | Z70: Payload Target | AB70: Kelompok Minggu | AC70: Cycle Time Actual | AD70: Cycle Time Target | AF70: Kelompok Minggu | AG70: Fuel Ratio Actual | AH70: Fuel Ratio Target | AJ70: Kelompok Minggu | AK70: TPD Actual | AL70: TPD Target
A71: Jan | B71: =SUMIFS('Input Data Daily'!$I$5:$I$369,'Input Data Daily'!$A$5:$A$369,">="&DATE(2026,ROW()-70,1),'Input Data Daily'!$A$5:$A$369,"<"&EDATE(DATE(2026,ROW()-70,1),1)) -> 0 | C71: =SUMIF($D$5:$D$7,DATE(2026,ROW()-70,1),$E$5:$E$7) -> 0 | P71: =A15 -> W01 | Q71: =B15 | R71: =C15 -> 0.93 | T71: =A15 -> W01 | U71: =D15 | V71: =E15 -> 0.88 | X71: =A15 -> W01 | Y71: =F15 | Z71: =G15 -> 205 | AB71: =A15 -> W01 | AC71: =H15 | AD71: =I15 -> 7.5 | AF71: =A15 -> W01 | AG71: =J15 | AH71: =K15 -> 1.55 | AJ71: =A15 -> W01 | AK71: =L15 | AL71: =M15 -> 2.7
A72: Feb | B72: =SUMIFS('Input Data Daily'!$I$5:$I$369,'Input Data Daily'!$A$5:$A$369,">="&DATE(2026,ROW()-70,1),'Input Data Daily'!$A$5:$A$369,"<"&EDATE(DATE(2026,ROW()-70,1),1)) -> 0 | C72: =SUMIF($D$5:$D$7,DATE(2026,ROW()-70,1),$E$5:$E$7) -> 0 | P72: =A16 -> W02 | Q72: =B16 | R72: =C16 -> 0.93 | T72: =A16 -> W02 | U72: =D16 | V72: =E16 -> 0.88 | X72: =A16 -> W02 | Y72: =F16 | Z72: =G16 -> 205 | AB72: =A16 -> W02 | AC72: =H16 | AD72: =I16 -> 7.5 | AF72: =A16 -> W02 | AG72: =J16 | AH72: =K16 -> 1.55 | AJ72: =A16 -> W02 | AK72: =L16 | AL72: =M16 -> 2.7
A73: Mar | B73: =SUMIFS('Input Data Daily'!$I$5:$I$369,'Input Data Daily'!$A$5:$A$369,">="&DATE(2026,ROW()-70,1),'Input Data Daily'!$A$5:$A$369,"<"&EDATE(DATE(2026,ROW()-70,1),1)) -> 0 | C73: =SUMIF($D$5:$D$7,DATE(2026,ROW()-70,1),$E$5:$E$7) -> 0 | P73: =A17 -> W03 | Q73: =B17 | R73: =C17 -> 0.93 | T73: =A17 -> W03 | U73: =D17 | V73: =E17 -> 0.88 | X73: =A17 -> W03 | Y73: =F17 | Z73: =G17 -> 205 | AB73: =A17 -> W03 | AC73: =H17 | AD73: =I17 -> 7.5 | AF73: =A17 -> W03 | AG73: =J17 | AH73: =K17 -> 1.55 | AJ73: =A17 -> W03 | AK73: =L17 | AL73: =M17 -> 2.7
A74: Apr | B74: =SUMIFS('Input Data Daily'!$I$5:$I$369,'Input Data Daily'!$A$5:$A$369,">="&DATE(2026,ROW()-70,1),'Input Data Daily'!$A$5:$A$369,"<"&EDATE(DATE(2026,ROW()-70,1),1)) -> 0 | C74: =SUMIF($D$5:$D$7,DATE(2026,ROW()-70,1),$E$5:$E$7) -> 0 | P74: =A18 -> W04 | Q74: =B18 | R74: =C18 -> 0.93 | T74: =A18 -> W04 | U74: =D18 | V74: =E18 -> 0.88 | X74: =A18 -> W04 | Y74: =F18 | Z74: =G18 -> 205 | AB74: =A18 -> W04 | AC74: =H18 | AD74: =I18 -> 7.5 | AF74: =A18 -> W04 | AG74: =J18 | AH74: =K18 -> 1.55 | AJ74: =A18 -> W04 | AK74: =L18 | AL74: =M18 -> 2.7
A75: May | B75: =SUMIFS('Input Data Daily'!$I$5:$I$369,'Input Data Daily'!$A$5:$A$369,">="&DATE(2026,ROW()-70,1),'Input Data Daily'!$A$5:$A$369,"<"&EDATE(DATE(2026,ROW()-70,1),1)) -> 0 | C75: =SUMIF($D$5:$D$7,DATE(2026,ROW()-70,1),$E$5:$E$7) -> 0 | P75: =A19 -> W05 | Q75: =B19 | R75: =C19 -> 0.93 | T75: =A19 -> W05 | U75: =D19 | V75: =E19 -> 0.88 | X75: =A19 -> W05 | Y75: =F19 | Z75: =G19 -> 205 | AB75: =A19 -> W05 | AC75: =H19 | AD75: =I19 -> 7.5 | AF75: =A19 -> W05 | AG75: =J19 | AH75: =K19 -> 1.55 | AJ75: =A19 -> W05 | AK75: =L19 | AL75: =M19 -> 2.7
A76: Jun | B76: =SUMIFS('Input Data Daily'!$I$5:$I$369,'Input Data Daily'!$A$5:$A$369,">="&DATE(2026,ROW()-70,1),'Input Data Daily'!$A$5:$A$369,"<"&EDATE(DATE(2026,ROW()-70,1),1)) -> 0 | C76: =SUMIF($D$5:$D$7,DATE(2026,ROW()-70,1),$E$5:$E$7) -> 0 | P76: =A20 -> W06 | Q76: =B20 | R76: =C20 -> 0.93 | T76: =A20 -> W06 | U76: =D20 | V76: =E20 -> 0.88 | X76: =A20 -> W06 | Y76: =F20 | Z76: =G20 -> 205 | AB76: =A20 -> W06 | AC76: =H20 | AD76: =I20 -> 7.5 | AF76: =A20 -> W06 | AG76: =J20 | AH76: =K20 -> 1.55 | AJ76: =A20 -> W06 | AK76: =L20 | AL76: =M20 -> 2.7
A77: Jul | B77: =SUMIFS('Input Data Daily'!$I$5:$I$369,'Input Data Daily'!$A$5:$A$369,">="&DATE(2026,ROW()-70,1),'Input Data Daily'!$A$5:$A$369,"<"&EDATE(DATE(2026,ROW()-70,1),1)) -> 0 | C77: =SUMIF($D$5:$D$7,DATE(2026,ROW()-70,1),$E$5:$E$7) -> 0 | P77: =A21 -> W07 | Q77: =B21 | R77: =C21 -> 0.93 | T77: =A21 -> W07 | U77: =D21 | V77: =E21 -> 0.88 | X77: =A21 -> W07 | Y77: =F21 | Z77: =G21 -> 205 | AB77: =A21 -> W07 | AC77: =H21 | AD77: =I21 -> 7.5 | AF77: =A21 -> W07 | AG77: =J21 | AH77: =K21 -> 1.55 | AJ77: =A21 -> W07 | AK77: =L21 | AL77: =M21 -> 2.7
A78: Aug | B78: =SUMIFS('Input Data Daily'!$I$5:$I$369,'Input Data Daily'!$A$5:$A$369,">="&DATE(2026,ROW()-70,1),'Input Data Daily'!$A$5:$A$369,"<"&EDATE(DATE(2026,ROW()-70,1),1)) -> 74558 | C78: =SUMIF($D$5:$D$7,DATE(2026,ROW()-70,1),$E$5:$E$7) -> 32000 | P78: =A22 -> W08 | Q78: =B22 | R78: =C22 -> 0.93 | T78: =A22 -> W08 | U78: =D22 | V78: =E22 -> 0.88 | X78: =A22 -> W08 | Y78: =F22 | Z78: =G22 -> 205 | AB78: =A22 -> W08 | AC78: =H22 | AD78: =I22 -> 7.5 | AF78: =A22 -> W08 | AG78: =J22 | AH78: =K22 -> 1.55 | AJ78: =A22 -> W08 | AK78: =L22 | AL78: =M22 -> 2.7
A79: Sep | B79: =SUMIFS('Input Data Daily'!$I$5:$I$369,'Input Data Daily'!$A$5:$A$369,">="&DATE(2026,ROW()-70,1),'Input Data Daily'!$A$5:$A$369,"<"&EDATE(DATE(2026,ROW()-70,1),1)) -> 216232.85 | C79: =SUMIF($D$5:$D$7,DATE(2026,ROW()-70,1),$E$5:$E$7) -> 398000 | P79: =A23 -> W09 | Q79: =B23 | R79: =C23 -> 0.93 | T79: =A23 -> W09 | U79: =D23 | V79: =E23 -> 0.88 | X79: =A23 -> W09 | Y79: =F23 | Z79: =G23 -> 205 | AB79: =A23 -> W09 | AC79: =H23 | AD79: =I23 -> 7.5 | AF79: =A23 -> W09 | AG79: =J23 | AH79: =K23 -> 1.55 | AJ79: =A23 -> W09 | AK79: =L23 | AL79: =M23 -> 2.7
A80: Oct | B80: =SUMIFS('Input Data Daily'!$I$5:$I$369,'Input Data Daily'!$A$5:$A$369,">="&DATE(2026,ROW()-70,1),'Input Data Daily'!$A$5:$A$369,"<"&EDATE(DATE(2026,ROW()-70,1),1)) -> 279728.59 | C80: =SUMIF($D$5:$D$7,DATE(2026,ROW()-70,1),$E$5:$E$7) -> 671000 | P80: =A24 -> W10 | Q80: =B24 | R80: =C24 -> 0.93 | T80: =A24 -> W10 | U80: =D24 | V80: =E24 -> 0.88 | X80: =A24 -> W10 | Y80: =F24 | Z80: =G24 -> 205 | AB80: =A24 -> W10 | AC80: =H24 | AD80: =I24 -> 7.5 | AF80: =A24 -> W10 | AG80: =J24 | AH80: =K24 -> 1.55 | AJ80: =A24 -> W10 | AK80: =L24 | AL80: =M24 -> 2.7
A81: Nov | B81: =SUMIFS('Input Data Daily'!$I$5:$I$369,'Input Data Daily'!$A$5:$A$369,">="&DATE(2026,ROW()-70,1),'Input Data Daily'!$A$5:$A$369,"<"&EDATE(DATE(2026,ROW()-70,1),1)) -> 0 | C81: =SUMIF($D$5:$D$7,DATE(2026,ROW()-70,1),$E$5:$E$7) -> 0 | P81: =A25 -> W11 | Q81: =B25 | R81: =C25 -> 0.93 | T81: =A25 -> W11 | U81: =D25 | V81: =E25 -> 0.88 | X81: =A25 -> W11 | Y81: =F25 | Z81: =G25 -> 205 | AB81: =A25 -> W11 | AC81: =H25 | AD81: =I25 -> 7.5 | AF81: =A25 -> W11 | AG81: =J25 | AH81: =K25 -> 1.55 | AJ81: =A25 -> W11 | AK81: =L25 | AL81: =M25 -> 2.7
A82: Dec | B82: =SUMIFS('Input Data Daily'!$I$5:$I$369,'Input Data Daily'!$A$5:$A$369,">="&DATE(2026,ROW()-70,1),'Input Data Daily'!$A$5:$A$369,"<"&EDATE(DATE(2026,ROW()-70,1),1)) -> 0 | C82: =SUMIF($D$5:$D$7,DATE(2026,ROW()-70,1),$E$5:$E$7) -> 0 | P82: =A26 -> W12 | Q82: =B26 | R82: =C26 -> 0.93 | T82: =A26 -> W12 | U82: =D26 | V82: =E26 -> 0.88 | X82: =A26 -> W12 | Y82: =F26 | Z82: =G26 -> 205 | AB82: =A26 -> W12 | AC82: =H26 | AD82: =I26 -> 7.5 | AF82: =A26 -> W12 | AG82: =J26 | AH82: =K26 -> 1.55 | AJ82: =A26 -> W12 | AK82: =L26 | AL82: =M26 -> 2.7
P83: =A27 -> W13 | Q83: =B27 | R83: =C27 -> 0.93 | T83: =A27 -> W13 | U83: =D27 | V83: =E27 -> 0.88 | X83: =A27 -> W13 | Y83: =F27 | Z83: =G27 -> 205 | AB83: =A27 -> W13 | AC83: =H27 | AD83: =I27 -> 7.5 | AF83: =A27 -> W13 | AG83: =J27 | AH83: =K27 -> 1.55 | AJ83: =A27 -> W13 | AK83: =L27 | AL83: =M27 -> 2.7
P84: =A28 -> W14 | Q84: =B28 | R84: =C28 -> 0.93 | T84: =A28 -> W14 | U84: =D28 | V84: =E28 -> 0.88 | X84: =A28 -> W14 | Y84: =F28 | Z84: =G28 -> 205 | AB84: =A28 -> W14 | AC84: =H28 | AD84: =I28 -> 7.5 | AF84: =A28 -> W14 | AG84: =J28 | AH84: =K28 -> 1.55 | AJ84: =A28 -> W14 | AK84: =L28 | AL84: =M28 -> 2.7
...

Sheet Indikator KPI W30-W53
A1: Grafik Indikator KPI Produksi – W30 sampai W53
A2: Pencapaian aktual dan target per kelompok minggu, mengikuti data input KPI produksi 2026.
A4: Indikator | B4: Target
A5: ='Grafik KPI 2026'!A5 -> PA | B5: ='Grafik KPI 2026'!B5 -> 0.93
A6: ='Grafik KPI 2026'!A6 -> UA | B6: ='Grafik KPI 2026'!B6 -> 0.88
A7: ='Grafik KPI 2026'!A7 -> TPD | B7: ='Grafik KPI 2026'!B7 -> 2.7
A8: ='Grafik KPI 2026'!A8 -> Cycle Time | B8: ='Grafik KPI 2026'!B8 -> 7.5
A9: ='Grafik KPI 2026'!A9 -> Payload | B9: ='Grafik KPI 2026'!B9 -> 205
A10: ='Grafik KPI 2026'!A10 -> Fuel Ratio | B10: ='Grafik KPI 2026'!B10 -> 1.55
A13: Ringkasan Pencapaian Mingguan W30–W53
A14: Kelompok Minggu | B14: PA Actual | C14: PA Target | D14: UA Actual | E14: UA Target | F14: Payload Actual | G14: Payload Target | H14: Cycle Time Actual | I14: Cycle Time Target | J14: Fuel Ratio Actual | K14: Fuel Ratio Target | L14: TPD Actual | M14: TPD Target | N14: Produksi Actual (Ton)
A15: ='Grafik KPI 2026'!A44 -> W30 | B15: ='Grafik KPI 2026'!B44 | C15: ='Grafik KPI 2026'!C44 -> 0.93 | D15: ='Grafik KPI 2026'!D44 | E15: ='Grafik KPI 2026'!E44 -> 0.88 | F15: ='Grafik KPI 2026'!F44 | G15: ='Grafik KPI 2026'!G44 -> 205 | H15: ='Grafik KPI 2026'!H44 | ... N15: ='Grafik KPI 2026'!N44 -> 0
A16: ='Grafik KPI 2026'!A45 -> W31 | B16: ='Grafik KPI 2026'!B45 -> 0.98084 | C16: ='Grafik KPI 2026'!C45 -> 0.93 | D16: ='Grafik KPI 2026'!D45 -> 0.49427334 | E16: ='Grafik KPI 2026'!E45 -> 0.88 | F16: ='Grafik KPI 2026'!F45 -> 207.15493 | G16: ='Grafik KPI 2026'!G45 -> 205 | H16: ='Grafik KPI 2026'!H45 -> 11.296763 | ... N16: ='Grafik KPI 2026'!N45 -> 13214.55
A17: ='Grafik KPI 2026'!A46 -> W32 | B17: ='Grafik KPI 2026'!B46 -> 0.97647143 | C17: ='Grafik KPI 2026'!C46 -> 0.93 | D17: ='Grafik KPI 2026'!D46 -> 0.51370786 | E17: ='Grafik KPI 2026'!E46 -> 0.88 | F17: ='Grafik KPI 2026'!F46 -> 201.82162 | G17: ='Grafik KPI 2026'!G46 -> 205 | H17: ='Grafik KPI 2026'!H46 -> 10.928522 | ... N17: ='Grafik KPI 2026'!N46 -> 24647.15
A18: ='Grafik KPI 2026'!A47 -> W33 | B18: ='Grafik KPI 2026'!B47 -> 0.97 | C18: ='Grafik KPI 2026'!C47 -> 0.93 | D18: ='Grafik KPI 2026'!D47 -> 0.62967532 | E18: ='Grafik KPI 2026'!E47 -> 0.88 | F18: ='Grafik KPI 2026'!F47 -> 205.59218 | G18: ='Grafik KPI 2026'!G47 -> 205 | H18: ='Grafik KPI 2026'!H47 -> 12.414766 | ... N18: ='Grafik KPI 2026'!N47 -> 19858
A19: ='Grafik KPI 2026'!A48 -> W34 | B19: ='Grafik KPI 2026'!B48 | C19: ='Grafik KPI 2026'!C48 -> 0.93 | D19: ='Grafik KPI 2026'!D48 | E19: ='Grafik KPI 2026'!E48 -> 0.88 | F19: ='Grafik KPI 2026'!F48 | G19: ='Grafik KPI 2026'!G48 -> 205 | H19: ='Grafik KPI 2026'!H48 | ... N19: ='Grafik KPI 2026'!N48 -> 0
A20: ='Grafik KPI 2026'!A49 -> W35 | B20: ='Grafik KPI 2026'!B49 -> 0.9783 | C20: ='Grafik KPI 2026'!C49 -> 0.93 | D20: ='Grafik KPI 2026'!D49 -> 0.55890363 | E20: ='Grafik KPI 2026'!E49 -> 0.88 | F20: ='Grafik KPI 2026'!F49 -> 205.70298 | G20: ='Grafik KPI 2026'!G49 -> 205 | H20: ='Grafik KPI 2026'!H49 -> 9.2756071 | ... N20: ='Grafik KPI 2026'!N49 -> 28002.5
A21: ='Grafik KPI 2026'!A50 -> W36 | B21: ='Grafik KPI 2026'!B50 -> 0.97714286 | C21: ='Grafik KPI 2026'!C50 -> 0.93 | D21: ='Grafik KPI 2026'!D50 -> 0.5361858 | E21: ='Grafik KPI 2026'!E50 -> 0.88 | F21: ='Grafik KPI 2026'!F50 -> 206.13746 | G21: ='Grafik KPI 2026'!G50 -> 205 | H21: ='Grafik KPI 2026'!H50 -> 8.8385557 | ... N21: ='Grafik KPI 2026'!N50 -> 53901
A22: ='Grafik KPI 2026'!A51 -> W37 | B22: ='Grafik KPI 2026'!B51 -> 0.99 | C22: ='Grafik KPI 2026'!C51 -> 0.93 | D22: ='Grafik KPI 2026'!D51 -> 0.40697459 | E22: ='Grafik KPI 2026'!E51 -> 0.88 | F22: ='Grafik KPI 2026'!F51 -> 209.12289 | G22: ='Grafik KPI 2026'!G51 -> 205 | H22: ='Grafik KPI 2026'!H51 -> 6.8638621 | ... N22: ='Grafik KPI 2026'!N51 -> 13122.95
A23: ='Grafik KPI 2026'!A52 -> W38 | B23: ='Grafik KPI 2026'!B52 -> 0.97833333 | C23: ='Grafik KPI 2026'!C52 -> 0.93 | D23: ='Grafik KPI 2026'!D52 -> 0.47260822 | E23: ='Grafik KPI 2026'!E52 -> 0.88 | F23: ='Grafik KPI 2026'!F52 -> 206.76634 | G23: ='Grafik KPI 2026'!G52 -> 205 | H23: ='Grafik KPI 2026'!H52 -> 9.3969818 | ... N23: ='Grafik KPI 2026'!N52 -> 40318.2
A24: ='Grafik KPI 2026'!A53 -> W39 | B24: ='Grafik KPI 2026'!B53 -> 0.98457143 | C24: ='Grafik KPI 2026'!C53 -> 0.93 | D24: ='Grafik KPI 2026'!D53 -> 0.77337828 | E24: ='Grafik KPI 2026'!E53 -> 0.88 | F24: ='Grafik KPI 2026'!F53 -> 203.20998 | G24: ='Grafik KPI 2026'!G53 -> 205 | H24: ='Grafik KPI 2026'!H53 -> 6.9223641 | ... N24: ='Grafik KPI 2026'!N53 -> 97726.5
A25: ='Grafik KPI 2026'!A54 -> W40 | B25: ='Grafik KPI 2026'!B54 -> 0.971 | C25: ='Grafik KPI 2026'!C54 -> 0.93 | D25: ='Grafik KPI 2026'!D54 -> 0.81661529 | E25: ='Grafik KPI 2026'!E54 -> 0.88 | F25: ='Grafik KPI 2026'!F54 -> 204.21473 | G25: ='Grafik KPI 2026'!G54 -> 205 | H25: ='Grafik KPI 2026'!H54 -> 8.2388707 | ... N25: ='Grafik KPI 2026'!N54 -> 125803.7
A26: ='Grafik KPI 2026'!A55 -> W41 | B26: ='Grafik KPI 2026'!B55 -> 0.96235 | C26: ='Grafik KPI 2026'!C55 -> 0.93 | D26: ='Grafik KPI 2026'!D55 -> 0.83829442 | E26: ='Grafik KPI 2026'!E55 -> 0.88 | F26: ='Grafik KPI 2026'!F55 -> 205.54365 | G26: ='Grafik KPI 2026'!G55 -> 205 | H26: ='Grafik KPI 2026'!H55 -> 8.7175884 | ... N26: ='Grafik KPI 2026'!N55 -> 153924.9
... A38: ='Grafik KPI 2026'!A67 -> W53 | B38: ='Grafik KPI 2026'!B67 | C38: ='Grafik KPI 2026'!C67 -> 0.93 | D38: ='Grafik KPI 2026'!D67 | E38: ='Grafik KPI 2026'!E67 -> 0.88 | F38: ='Grafik KPI 2026'!F67 | G38: ='Grafik KPI 2026'!G67 -> 205 | H38: ='Grafik KPI 2026'!H67 | ... N38: ='Grafik KPI 2026'!N67 -> 0
A42: Kelompok Minggu | B42: Produksi Actual (Ton)
A43: =A15 -> W30 | B43: =N15 -> 0
A44: =A16 -> W31 | B44: =N16 -> 13214.55
A45: =A17 -> W32 | B45: =N17 -> 24647.15
A46: =A18 -> W33 | B46: =N18 -> 19858
A47: =A19 -> W34 | B47: =N19 -> 0
A48: =A20 -> W35 | B48: =N20 -> 28002.5
A49: =A21 -> W36 | B49: =N21 -> 53901
A50: =A22 -> W37 | B50: =N22 -> 13122.95
A51: =A23 -> W38 | B51: =N23 -> 40318.2
A52: =A24 -> W39 | B52: =N24 -> 97726.5
A53: =A25 -> W40 | B53: =N25 -> 125803.7
A54: =A26 -> W41 | B54: =N26 -> 153924.9
... A66: =A38 -> W53 | B66: =N38 -> 0
P75: Kelompok Minggu | Q75: PA Actual | R75: PA Target | T75: Kelompok Minggu | U75: UA Actual | V75: UA Target | X75: Kelompok Minggu | Y75: Payload Actual | Z75: Payload Target | AB75: Kelompok Minggu | AC75: Cycle Time Actual | AD75: Cycle Time Target | AF75: Kelompok Minggu | AG75: Fuel Ratio Actual | AH75: Fuel Ratio Target | AJ75: Kelompok Minggu | AK75: TPD Actual | AL75: TPD Target
P76: =A15 -> W30 | Q76: =B15 | R76: =C15 -> 0.93 | T76: =A15 -> W30 | U76: 0 | V76: =E15 -> 0.88 | X76: =A15 -> W30 | Y76: 0 | Z76: =G15 -> 205 | AB76: =A15 -> W30 | AC76: 0 | AD76: =I15 -> 7.5 | AF76: =A15 -> W30 | AG76: =J15 | AH76: =K15 -> 1.55 | AJ76: =A15 -> W30 | AK76: 0 | AL76: =M15 -> 2.7
...

Sheet Kalkulator UA
A1: Kalkulator UA Berdasarkan Trip per Hari dan PA
A2: Ubah hanya sel berwarna kuning. Nilai UA dihitung dari PA, waktu efektif, dan pencapaian trip.
A5: Input | B5: Nilai | C5: Satuan / Keterangan
A6: Waktu kalender | B6: 24 | C6: jam per hari
A7: Planned delay | B7: 2.3333333 | C7: jam per hari (istirahat, refuel, change shift, cooling tyre)
A8: PA | B8: 1 | C8: masukkan sebagai persentase
A9: Target trip per hari | B9: 3 | C9: trip
A10: Trip aktual per hari | B10: 3.03 | C10: trip
A13: Hasil Perhitungan | B13: Nilai | C13: Rumus
A14: UA potensial | B14: =(B6-B7)/B6 -> 0.90277778 | C14: (Waktu kalender − planned delay) ÷ waktu kalender
A15: Pencapaian trip | B15: =B10/B9 -> 1.01 | C15: Trip aktual ÷ target trip
A16: Waktu kerja ekuivalen | B16: =(B6-B7)*B15 -> 21.883333 | C16: Waktu efektif × pencapaian trip
A17: Lost time operasional | B17: =(B6-B7)-B16 -> -0.21666667 | C17: Waktu efektif − waktu kerja ekuivalen
A18: UA aktual | B18: =MIN(1,B8*B14*B15) -> 0.91180556 | C18: PA × UA potensial × pencapaian trip
A19: Selisih terhadap UA potensial | B19: =B14-B18 -> -0.0090277778 | C19: UA potensial − UA aktual
A22: Contoh dokumen: PA 100%, target 3 trip, aktual 2,8 trip menghasilkan UA aktual 84,3%.
A24: Catatan
A25: Rumus UA kalender | B25: = PA × ((Waktu Kalender − Planned Delay) ÷ Waktu Kalender) × (Trip Aktual ÷ Target Trip)
A26: Penggunaan | B26: Bila PA 95%, masukkan 95% pada sel input PA. Rumus otomatis menyesuaikan UA.
